Workbook
Name Slicer_status: #N/A
Name Slicer_Credential_Type: #N/A
Name Slicer_Role: #N/A
Name Slicer_Department: #N/A

Sheet main
A1: Employee_ID | B1: Employee_Name | C1: Department | D1: Role | E1: Credential_Type | F1: Issue_Date | G1: Expiry_Date | H1: Credential_Status
A2: 10001 | B2: Rahul 755 | C2: HR | D2: Manager | E2: System Access | F2: 45155 | G2: 45335 | H2: Expired
A3: 10002 | B3: Rahul 33 | C3: Compliance | D3: Administrator | E3: ID Card | F3: 45531 | G3: 45896 | H3: Expired
A4: 10003 | B4: Amit 28 | C4: HR | D4: Analyst | E4: System Access | F4: 45444 | G4: 46174 | H4: Active
A5: 10004 | B5: Ravi 604 | C5: IT | D5: Administrator | E5: Compliance Certificate | F5: 45152 | G5: 45517 | H5: Expired
A6: 10005 | B6: Anil 160 | C6: HR | D6: Analyst | E6: Compliance Certificate | F6: 45275 | G6: 45640 | H6: Expired
A7: 10006 | B7: Neha 368 | C7: Finance | D7: Executive | E7: ID Card | F7: 45316 | G7: 45496 | H7: Expired
A8: 10007 | B8: Kiran 128 | C8: Sales | D8: Manager | E8: ID Card | F8: 45397 | G8: 46127 | H8: Active
A9: 10008 | B9: Suresh 907 | C9: HR | D9: Administrator | E9: Safety Training | F9: 45570 | G9: 46300 | H9: Active
A10: 10009 | B10: Kiran 234 | C10: Sales | D10: Analyst | E10: ID Card | F10: 44973 | G10: 45703 | H10: Expired
A11: 10010 | B11: Anil 465 | C11: HR | D11: Analyst | E11: ID Card | F11: 45316 | G11: 45681 | H11: Expired
A12: 10011 | B12: Kiran 274 | C12: IT | D12: Manager | E12: Safety Training | F12: 45141 | G12: 45871 | H12: Expired
A13: 10012 | B13: Rahul 474 | C13: Sales | D13: Analyst | E13: NDA | F13: 45177 | G13: 45357 | H13: Expired
... A5001: 15000 | B5001: Ravi 308 | C5001: Sales | D5001: Analyst | E5001: Safety Training | F5001: 45383 | G5001: 45563 | H5001: Expired

Sheet feauture engeneering
A1: Employee_ID | B1: Employee_Name | C1: DEPARTMENT | D1: Role | E1: Credential type | F1: issue_date | G1: Expiry_Date | H1: Credential_Status | I1: dayes to expiry | J1: status | K1: risk level | L1: action needed
A2: 10001 | B2: Rahul 755 | C2: HR | D2: Manager | E2: System Access | F2: 45155 | G2: 45335 | H2: Expired | I2: =G2-TODAY() -> -958 | J2: {=_xlfn.IFS(I2>30,"not expired",I2<0,"expired",I2<=30,"expiring soon")} -> expired | K2: {=_xlfn.IFS(J2="expired","high",J2="not expired","low",J2="expiring soon","mid")} -> high | L2: {=_xlfn.IFS(K2="high","renewal",K2="low","no need",K2="mid","upcoming renewal")} -> renewal
A3: 10002 | B3: Rahul 33 | C3: Compliance | D3: Administrator | E3: ID Card | F3: 45531 | G3: 45896 | H3: Expired | I3: =G3-TODAY() -> -397 | J3: {=_xlfn.IFS(I3>30,"not expired",I3<0,"expired",I3<=30,"expiring soon")} -> expired | K3: {=_xlfn.IFS(J3="expired","high",J3="not expired","low",J3="expiring soon","mid")} -> high | L3: {=_xlfn.IFS(K3="high","renewal",K3="low","no need",K3="mid","upcoming renewal")} -> renewal
A4: 10003 | B4: Amit 28 | C4: HR | D4: Analyst | E4: System Access | F4: 45444 | G4: 46174 | H4: Active | I4: =G4-TODAY() -> -119 | J4: {=_xlfn.IFS(I4>30,"not expired",I4<0,"expired",I4<=30,"expiring soon")} -> expired | K4: {=_xlfn.IFS(J4="expired","high",J4="not expired","low",J4="expiring soon","mid")} -> high | L4: {=_xlfn.IFS(K4="high","renewal",K4="low","no need",K4="mid","upcoming renewal")} -> renewal
A5: 10004 | B5: Ravi 604 | C5: IT | D5: Administrator | E5: Compliance Certificate | F5: 45152 | G5: 45517 | H5: Expired | I5: =G5-TODAY() -> -776 | J5: {=_xlfn.IFS(I5>30,"not expired",I5<0,"expired",I5<=30,"expiring soon")} -> expired | K5: {=_xlfn.IFS(J5="expired","high",J5="not expired","low",J5="expiring soon","mid")} -> high | L5: {=_xlfn.IFS(K5="high","renewal",K5="low","no need",K5="mid","upcoming renewal")} -> renewal
A6: 10005 | B6: Anil 160 | C6: HR | D6: Analyst | E6: Compliance Certificate | F6: 45275 | G6: 45640 | H6: Expired | I6: =G6-TODAY() -> -653 | J6: {=_xlfn.IFS(I6>30,"not expired",I6<0,"expired",I6<=30,"expiring soon")} -> expired | K6: {=_xlfn.IFS(J6="expired","high",J6="not expired","low",J6="expiring soon","mid")} -> high | L6: {=_xlfn.IFS(K6="high","renewal",K6="low","no need",K6="mid","upcoming renewal")} -> renewal
A7: 10006 | B7: Neha 368 | C7: Finance | D7: Executive | E7: ID Card | F7: 45316 | G7: 45496 | H7: Expired | I7: =G7-TODAY() -> -797 | J7: {=_xlfn.IFS(I7>30,"not expired",I7<0,"expired",I7<=30,"expiring soon")} -> expired | K7: {=_xlfn.IFS(J7="expired","high",J7="not expired","low",J7="expiring soon","mid")} -> high | L7: {=_xlfn.IFS(K7="high","renewal",K7="low","no need",K7="mid","upcoming renewal")} -> renewal
A8: 10007 | B8: Kiran 128 | C8: Sales | D8: Manager | E8: ID Card | F8: 45397 | G8: 46127 | H8: Active | I8: =G8-TODAY() -> -166 | J8: {=_xlfn.IFS(I8>30,"not expired",I8<0,"expired",I8<=30,"expiring soon")} -> expired | K8: {=_xlfn.IFS(J8="expired","high",J8="not expired","low",J8="expiring soon","mid")} -> high | L8: {=_xlfn.IFS(K8="high","renewal",K8="low","no need",K8="mid","upcoming renewal")} -> renewal
A9: 10008 | B9: Suresh 907 | C9: HR | D9: Administrator | E9: Safety Training | F9: 45570 | G9: 46300 | H9: Active | I9: =G9-TODAY() -> 7 | J9: {=_xlfn.IFS(I9>30,"not expired",I9<0,"expired",I9<=30,"expiring soon")} -> expiring soon | K9: {=_xlfn.IFS(J9="expired","high",J9="not expired","low",J9="expiring soon","mid")} -> mid | L9: {=_xlfn.IFS(K9="high","renewal",K9="low","no need",K9="mid","upcoming renewal")} -> upcoming renewal
A10: 10009 | B10: Kiran 234 | C10: Sales | D10: Analyst | E10: ID Card | F10: 44973 | G10: 45703 | H10: Expired | I10: =G10-TODAY() -> -590 | J10: {=_xlfn.IFS(I10>30,"not expired",I10<0,"expired",I10<=30,"expiring soon")} -> expired | K10: {=_xlfn.IFS(J10="expired","high",J10="not expired","low",J10="expiring soon","mid")} -> high | L10: {=_xlfn.IFS(K10="high","renewal",K10="low","no need",K10="mid","upcoming renewal")} -> renewal
A11: 10010 | B11: Anil 465 | C11: HR | D11: Analyst | E11: ID Card | F11: 45316 | G11: 45681 | H11: Expired | I11: =G11-TODAY() -> -612 | J11: {=_xlfn.IFS(I11>30,"not expired",I11<0,"expired",I11<=30,"expiring soon")} -> expired | K11: {=_xlfn.IFS(J11="expired","high",J11="not expired","low",J11="expiring soon","mid")} -> high | L11: {=_xlfn.IFS(K11="high","renewal",K11="low","no need",K11="mid","upcoming renewal")} -> renewal
A12: 10011 | B12: Kiran 274 | C12: IT | D12: Manager | E12: Safety Training | F12: 45141 | G12: 45871 | H12: Expired | I12: =G12-TODAY() -> -422 | J12: {=_xlfn.IFS(I12>30,"not expired",I12<0,"expired",I12<=30,"expiring soon")} -> expired | K12: {=_xlfn.IFS(J12="expired","high",J12="not expired","low",J12="expiring soon","mid")} -> high | L12: {=_xlfn.IFS(K12="high","renewal",K12="low","no need",K12="mid","upcoming renewal")} -> renewal
A13: 10012 | B13: Rahul 474 | C13: Sales | D13: Analyst | E13: NDA | F13: 45177 | G13: 45357 | H13: Expired | I13: =G13-TODAY() -> -936 | J13: {=_xlfn.IFS(I13>30,"not expired",I13<0,"expired",I13<=30,"expiring soon")} -> expired | K13: {=_xlfn.IFS(J13="expired","high",J13="not expired","low",J13="expiring soon","mid")} -> high | L13: {=_xlfn.IFS(K13="high","renewal",K13="low","no need",K13="mid","upcoming renewal")} -> renewal
... A5001: 15000 | B5001: Ravi 308 | C5001: Sales | D5001: Analyst | E5001: Safety Training | F5001: 45383 | G5001: 45563 | H5001: Expired | I5001: =G5001-TODAY() -> -730 | J5001: {=_xlfn.IFS(I5001>30,"not expired",I5001<0,"expired",I5001<=30,"expiring soon")} -> expired | K5001: {=_xlfn.IFS(J5001="expired","high",J5001="not expired","low",J5001="expiring soon","mid")} -> high | L5001: {=_xlfn.IFS(K5001="high","renewal",K5001="low","no need",K5001="mid","upcoming renewal")} -> renewal

Sheet kpi
A1: total no of employees | B1: =COUNT('feauture engeneering'!A2:A5001) -> 5000
A2: total active employees | B2: =COUNTIF('feauture engeneering'!H2:H5001,"active") -> 746
A3: total expired employees | B3: =COUNTIF('feauture engeneering'!H2:H5001,"expired") -> 4254
A4: total expiring soon employees | B4: =COUNTIF('feauture engeneering'!J2:J5001,"expiring soon") -> 71
A8: *immmediate action required | B8: =COUNTIF('feauture engeneering'!K2:K5001,"high") -> 4836

Sheet tables
A3: Sum of Employee_ID | B3: status
A4: Department | B4: expired | C4: expiring soon | D4: not expired | E4: Grand Total
A5: Compliance | B5: 9925546 | C5: 200209 | D5: 174965 | E5: 10300720
A6: Finance | B6: 9708406 | C6: 88577 | D6: 171672 | E6: 9968655
A7: HR | B7: 9889292 | C7: 208973 | D7: 137968 | E7: 10236233
A8: IT | B8: 10274451 | C8: 125313 | D8: 144148 | E8: 10543912
A9: Operations | B9: 10409910 | C9: 203450 | D9: 200422 | E9: 10813782
A10: Sales | B10: 10225309 | C10: 104666 | D10: 309223 | E10: 10639198
A11: Grand Total | B11: 60432914 | C11: 931188 | D11: 1138398 | E11: 62502500
A16: Sum of Employee_ID | B16: Credential_Type
A17: Credential_Status | B17: Compliance Certificate | C17: ID Card | D17: NDA | E17: Safety Training | F17: System Access | G17: Grand Total
A18: Active | B18: 1901904 | C18: 1881589 | D18: 1687949 | E18: 2096041 | F18: 1708199 | G18: 9275682
A19: Expired | B19: 10997698 | C19: 10852622 | D19: 10890620 | E19: 10485350 | F19: 10000528 | G19: 53226818
A20: Grand Total | B20: 12899602 | C20: 12734211 | D20: 12578569 | E20: 12581391 | F20: 11708727 | G20: 62502500
A23: Role | B23: Count of status
A24: Administrator | B24: 1013
A25: Analyst | B25: 1007
A26: Executive | B26: 1006
A27: Lead | B27: 1018
A28: Manager | B28: 956
A29: Grand Total | B29: 5000
A31: status | B31: (ALL)
A33: Employee_Name | B33: Department | C33: dayes to expiry | D33: Credential_Type
A34: Amit 1
B35: Compliance
C36: 62
D37: Safety Training
B38: Sales
C39: -46
D40: System Access
A41: Amit 101
B42: Finance
C43: -788
D44: Compliance Certificate
A45: Amit 104
B46: Finance
C47: -822
D48: Compliance Certificate
A49: Amit 105
B50: Compliance
...

Sheet charts
A3: Sum of Employee_ID | B3: status
A4: Department | B4: expired | C4: expiring soon | D4: not expired | E4: Grand Total
A5: Compliance | B5: 9925546 | C5: 200209 | D5: 174965 | E5: 10300720
A6: Finance | B6: 9708406 | C6: 88577 | D6: 171672 | E6: 9968655
A7: HR | B7: 9889292 | C7: 208973 | D7: 137968 | E7: 10236233
A8: IT | B8: 10274451 | C8: 125313 | D8: 144148 | E8: 10543912
A9: Operations | B9: 10409910 | C9: 203450 | D9: 200422 | E9: 10813782
A10: Sales | B10: 10225309 | C10: 104666 | D10: 309223 | E10: 10639198
A11: Grand Total | B11: 60432914 | C11: 931188 | D11: 1138398 | E11: 62502500
A16: Sum of Employee_ID | B16: Credential_Type
A17: Credential_Status | B17: Compliance Certificate | C17: ID Card | D17: NDA | E17: Safety Training | F17: System Access | G17: Grand Total
A18: Active | B18: 1901904 | C18: 1881589 | D18: 1687949 | E18: 2096041 | F18: 1708199 | G18: 9275682
A19: Expired | B19: 10997698 | C19: 10852622 | D19: 10890620 | E19: 10485350 | F19: 10000528 | G19: 53226818
A20: Grand Total | B20: 12899602 | C20: 12734211 | D20: 12578569 | E20: 12581391 | F20: 11708727 | G20: 62502500
A39: Role | B39: Count of status
A40: Administrator | B40: 1013
A41: Analyst | B41: 1007
A42: Executive | B42: 1006
A43: Lead | B43: 1018
A44: Manager | B44: 956
A45: Grand Total | B45: 5000

Sheet dashboard

Sheet DATA VALIDATION
A1: EMPLOYEE NAME | B1: Rahul 755 | C1: =VLOOKUP(B1,'feauture engeneering'!B2:L5001,2,0) -> HR | D1: xlookups | E1: =_xlfn.XLOOKUP(B1,'feauture engeneering'!B$2:B$5001,'feauture engeneering'!E$2:E$5001,"not found",0) -> System Access
A2: DEPARTMENT | B2: Finance | C2: =IFERROR(VLOOKUP(B2,'feauture engeneering'!C1:L5001,3,0),"error") -> ID Card | E2: =_xlfn.XLOOKUP(B2,'feauture engeneering'!C$2:C$5001,'feauture engeneering'!E$2:E$5001,"not found",0) -> ID Card
A3: CREDENTIANLS | B3: Safety Training | C3: =VLOOKUP(B3,'feauture engeneering'!E1:L5001,5,0) -> 7 | E3: =_xlfn.XLOOKUP(B3,'feauture engeneering'!E3:E5002,'feauture engeneering'!D3:D5002,"not found",0) -> Administrator
A4: EXPIRY DATE | B4: 45871 | C4: =IFERROR(VLOOKUP(B4,'feauture engeneering'!G1:L5001,3,0),"not found") -> -422 | E4: =_xlfn.XLOOKUP(B4,'feauture engeneering'!G4:G5003,'feauture engeneering'!D4:D5003,"not found",0) -> Manager

Sheet indexmatch
B3: ENTER THE ID OF EMPLOYEES | C3: 10080
B10: RESULTS
B11: NAME | C11: {=INDEX('feauture engeneering'!B2:B5001,MATCH(C3,'feauture engeneering'!A2:A5001,0))} -> Neha 291
B12: STATUS | C12: {=INDEX('feauture engeneering'!J2:J5001,MATCH(C3,'feauture engeneering'!A2:A5001))} -> expired
B13: ACTION REQUIRED | C13: {=INDEX('feauture engeneering'!L2:L5001,MATCH(C3,'feauture engeneering'!A2:A5001,))} -> renewal
B14: DAYS TO EXPIRED/DAYS REMAINING | C14: {=INDEX('feauture engeneering'!I1:I5001,MATCH(C3,'feauture engeneering'!A1:A5001))} -> -512
